<?xml version="1.0" ?>
<sdf version="1.4">

<!-- 
    author: liuweiwei <liuweiwei02@baidu.com>
    a car that composed of five links:
        car body
        and four wheels
-->


<model name="car">
    <link name="body">
        <self_collide>true</self_collide>
        <pose> 0 0 0.5 0 0 0 </pose>
        <collision name="cbody">
            <geometry>
                <mesh> 
                    <uri>model://car/meshes/carbody.dae</uri>
                    <scale> 100 100 100 </scale>
                </mesh>
            </geometry>
        </collision>
        <visual name="vbody">
            <geometry>
                <mesh> 
                    <uri>model://car/meshes/carbody.dae</uri>
                    <scale> 100 100 100 </scale>
                </mesh>
            </geometry>
        </visual>
    </link>
    <link name="FLwheel">
        <pose> 1.5 -0.85 0.5 0 0 0 </pose>
        <collision name="cflwheel">
            <pose> 0 0 0 -1.5708 0 0 </pose>
            <geometry>
                <cylinder>
                    <radius>0.5</radius>
                    <length>0.3</length>
                </cylinder>
            </geometry>
        </collision>
        <visual name="vflwheel">
            <pose> 0 0 0 -1.5708 0 0 </pose>
            <geometry>
                <cylinder>
                    <radius>0.5</radius>
                    <length>0.3</length>
                </cylinder>
            </geometry>
        </visual>
    </link>
    <link name="FRwheel">
        <pose> 1.5 0.85 0.5 0 0 0 </pose>
        <collision name="cfrwheel">
            <pose> 0 0 0 -1.5708 0 0 </pose>
            <geometry>
                <cylinder>
                    <radius>0.5</radius>
                    <length>0.3</length>
                </cylinder>
            </geometry>
        </collision>
        <visual name="vfrwheel">
            <pose> 0 0 0 -1.5708 0 0 </pose>
            <geometry>
                <cylinder>
                    <radius>0.5</radius>
                    <length>0.3</length>
                </cylinder>
            </geometry>
        </visual>
    </link>
    <link name="TRwheel">
        <pose> -1.5 0.85 0.5 0 0 0 </pose>
        <collision name="ctrwheel">
            <pose> 0 0 0 -1.5708 0 0 </pose>
            <geometry>
                <cylinder>
                    <radius>0.5</radius>
                    <length>0.3</length>
                </cylinder>
            </geometry>
        </collision>
        <visual name="vtrwheel">
            <pose> 0 0 0 -1.5708 0 0 </pose>
            <geometry>
                <cylinder>
                    <radius>0.5</radius>
                    <length>0.3</length>
                </cylinder>
            </geometry>
        </visual>
    </link>
    <link name="TLwheel">
        <pose> -1.5 -0.85 0.5 0 0 0 </pose>
        <collision name="ctlwheel">
            <pose> 0 0 0 -1.5708 0 0 </pose>
            <geometry>
                <cylinder>
                    <radius>0.5</radius>
                    <length>0.3</length>
                </cylinder>
            </geometry>
        </collision>
        <visual name="vtlwheel">
            <pose> 0 0 0 -1.5708 0 0 </pose>
            <geometry>
                <cylinder>
                    <radius>0.5</radius>
                    <length>0.3</length>
                </cylinder>
            </geometry>
        </visual>
    </link>
    <link name="FRwheel_steer">
        <pose>1.5 0.85 0.5 0 0 0</pose>
    </link>
    <link name="FLwheel_steer">
        <pose>1.5 -0.85 0.5 0 0 0</pose>
    </link>

    <joint name="jFRsteer" type="revolute">
        <parent>body</parent>
        <child>FRwheel_steer</child>
        <axis>
            <xyz>0 0 1</xyz>
            <limit>
                <upper>0.8</upper>
                <lower>-0.8</lower>
            </limit>
            <dynamics>
                <friction>2.0</friction>
            </dynamics>
        </axis>
    </joint>
    <joint name="jFLsteer" type="revolute">
        <parent>body</parent>
        <child>FLwheel_steer</child>
        <axis>
            <xyz>0 0 1</xyz>
            <limit>
                <upper>0.8</upper>
                <lower>-0.8</lower>
            </limit>
            <dynamics>
                <friction>2.0</friction>
            </dynamics>
        </axis>
    </joint>
    <joint name="jFR" type="revolute">
        <parent>FRwheel_steer</parent>
        <child>FRwheel</child>
        <axis>
            <xyz>0 1 0</xyz>
        </axis>
    </joint>
    <joint name="jFL" type="revolute">
        <parent>FLwheel_steer</parent>
        <child>FLwheel</child>
        <axis>
            <xyz>0 1 0</xyz>
        </axis>
    </joint>
    <joint name="jTR" type="revolute">
        <parent>body</parent>
        <child>TRwheel</child>
        <axis>
            <xyz>0 1 0</xyz>
        </axis>
    </joint>
    <joint name="jTL" type="revolute">
        <parent>body</parent>
        <child>TLwheel</child>
        <axis>
            <xyz>0 1 0</xyz>
        </axis>
    </joint>
    <plugin name="car_plugin" filename="libcar_model.dylib" />
</model>
</sdf>

